Workbook

Sheet Products
A1: Product Code | B1: Category | C1: Product Name | D1: Pricing Model | E1: Related Products Code | F1: Example
A2: POSM-001 | B2: POSM(MKT) | C2: ร่มโค้ก | D2: ต่อชิ้น
A3: POSM-002 | B3: POSM(MKT) | C3: กล่องทิชชู-โค้ก | D3: ต่อชิ้น
A4: POSM-003 | B4: POSM(MKT) | C4: ผ้ากันเปื้อนโคคา-โคล่า | D4: ต่อชิ้น
A5: POSM-004 | B5: POSM(MKT) | C5: ถังใส่น้ำแข็ง-โค้ก | D5: ต่อชิ้น
A6: POSM-005 | B6: POSM(MKT) | C6: กล่องใส่ช้อน/ตะเกียบ | D6: ต่อชิ้น
A7: POSM-006 | B7: POSM(MKT) | C7: ธงปีกนก | D7: ต่อชิ้น | E7: POSM-007
A8: POSM-007 | B8: POSM(MKT) | C8: ฐานน้ำ | D8: ต่อชิ้น
A9: POSM-008 | B9: Printing(MKT) | C9: Mega Rack | D9: ต่อชิ้น
A10: PRINT-001 | B10: Printing(MKT) | C10: PP Board | D10: ต่อชิ้น
A11: PRINT-002 | B11: Printing(MKT) | C11: ป้ายรายการอาหารโค้ก | D11: ต่อชิ้น
A12: PRINT-003 | B12: Printing(MKT) | C12: แบนเนอร์โค้ก | D12: ต่อชิ้น
A13: PRINT-004 | B13: Printing(MKT) | C13: ผ้าใบกันสาด-โค้ก | D13: ต่อชิ้น
A14: PRINT-005 | B14: Printing(MKT) | C14: แผ่นริจิ-โค้ก | D14: ต่อชิ้น
A15: GARMT-001 | B15: Garment | C15: เสื้อยืด | D15: ต่อชิ้น
A16: GARMT-002 | B16: Garment | C16: เสื้อโปโล TC | D16: ต่อชิ้น
A17: GARMT-003 | B17: Garment | C17: เสื้อโปโล ผ้าไมโคร | D17: ต่อชิ้น
A18: GARMT-004 | B18: Garment | C18: สกรีน | D18: ต่อชิ้น
A19: PREM-001 | B19: Premium | C19: แก้วกระดาษ | D19: ต่อชิ้น
... A21: PREM-004 | B21: Premium | C21: Bean Bag | D21: ต่อชิ้น
A22: PRINTR-001 | B22: Printing-Rate | C22: ป้ายไวนิล แบบปล่อยชาย | D22: ต่อ ตรม. | F22: 1m*3m=3m
A23: PRINTR-002 | B23: Printing-Rate | C23: ป้ายไวนิลหลังดำ แบบปล่อยชาย | D23: ต่อ ตรม.

Sheet Variants
A1: Product Code | B1: Variant Code | C1: Product Name | D1: Description | E1: Notes
A2: POSM-001 | B2: POSM-001-V1 | C2: =IFERROR(VLOOKUP(A2,Products!A:C,3,FALSE), "-") -> ร่มโค้ก | D2: 36 นิ้ว โครงเหล็ก สีตาย (ไม่เกิน 4 สี) | G2: {=IFERROR(VLOOKUP(B2, Table2[Variant Code],Table2[Description],""), "-")} -> -
A3: POSM-001 | B3: POSM-001-V2 | C3: =IFERROR(VLOOKUP(A3,Products!A:C,3,FALSE), "-") -> ร่มโค้ก | D3: 36 นิ้ว โครงเหล็ก ไล่ระดับสี (ไม่เกิน 8 เฉด)
A4: POSM-001 | B4: POSM-001-V3 | C4: =IFERROR(VLOOKUP(A4,Products!A:C,3,FALSE), "-") -> ร่มโค้ก | D4: 36 นิ้ว โครงไฟเบอร์ สีตาย (ไม่เกิน 4 สี)
A5: POSM-001 | B5: POSM-001-V4 | C5: =IFERROR(VLOOKUP(A5,Products!A:C,3,FALSE), "-") -> ร่มโค้ก | D5: 36 นิ้ว โครงไฟเบอร์ ไล่ระดับสี (ไม่เกิน 8 เฉด)
A6: POSM-001 | B6: POSM-001-V5 | C6: =IFERROR(VLOOKUP(A6,Products!A:C,3,FALSE), "-") -> ร่มโค้ก | D6: 40 นิ้ว โครงเหล็ก สีตาย (ไม่เกิน 4 สี)
A7: POSM-001 | B7: POSM-001-V6 | C7: =IFERROR(VLOOKUP(A7,Products!A:C,3,FALSE), "-") -> ร่มโค้ก | D7: 40 นิ้ว โครงเหล็ก ไล่ระดับสี (ไม่เกิน 8 เฉด)
A8: POSM-001 | B8: POSM-001-V7 | C8: =IFERROR(VLOOKUP(A8,Products!A:C,3,FALSE), "-") -> ร่มโค้ก | D8: 40 นิ้ว โครงไฟเบอร์ สีตาย (ไม่เกิน 4 สี)
A9: POSM-001 | B9: POSM-001-V8 | C9: =IFERROR(VLOOKUP(A9,Products!A:C,3,FALSE), "-") -> ร่มโค้ก | D9: 40 นิ้ว โครงไฟเบอร์ ไล่ระดับสี (ไม่เกิน 8 เฉด)
A10: POSM-003 | B10: POSM-003-V1 | C10: =IFERROR(VLOOKUP(A10,Products!A:C,3,FALSE), "-") -> ผ้ากันเปื้อนโคคา-โคล่า | D10: เอี้ยม (เต็มตัว) ไขว้หลัง
A11: POSM-003 | B11: POSM-003-V2 | C11: =IFERROR(VLOOKUP(A11,Products!A:C,3,FALSE), "-") -> ผ้ากันเปื้อนโคคา-โคล่า | D11: ครึ่งตัว
A12: POSM-006 | B12: POSM-006-V1 | C12: =IFERROR(VLOOKUP(A12,Products!A:C,3,FALSE), "-") -> ธงปีกนก | D12: 120x40x150 cm (TT-DSD)
A13: POSM-006 | B13: POSM-006-V2 | C13: =IFERROR(VLOOKUP(A13,Products!A:C,3,FALSE), "-") -> ธงปีกนก | D13: 150x60x150 cm (WS)
A14: PRINT-001 | B14: PRINT-001-V1 | C14: =IFERROR(VLOOKUP(A14,Products!A:C,3,FALSE), "-") -> PP Board | D14: 120x120 cm (โค้กเขียนชื่อร้านค้า)
... A34: PREM-001 | B34: PREM-001-V2 | C34: =IFERROR(VLOOKUP(A34,Products!A:C,3,FALSE), "-") -> แก้วกระดาษ | D34: 22 ออนซ์
A35: POSM-006 | B35: POSM-006-v1 | C35: =VLOOKUP(A35,Products!A:C,3,FALSE) -> ธงปีกนก | D35: XL
A36: POSM-007 | B36: POSM-007-v1 | C36: =VLOOKUP(A36,Products!A:C,3,FALSE) -> ฐานน้ำ | D36: 20 L

Sheet Vendors
A1: Vendor Code | B1: Vendor Name
A2: VEN-A | B2: Vendor A
A3: VEN-B | B3: Vendor B
A4: VEN-C | B4: Vendor C
A5: VEN-D | B5: Vendor D
A6: VEN-E | B6: Vendor E
A7: VEN-F | B7: Vendor F
A8: VEN-G | B8: Vendor G
A9: VEN-H | B9: Vendor H
A10: VEN-I | B10: Vendor I
A11: VEN-J | B11: Vendor J
A12: VEN-K | B12: Vendor K
... A16: VEN-O | B16: Vendor O

Sheet Vendor_Prices
A1: Product Code | B1: Variant Code | C1: Vendor Code | D1: Vendor Name | E1: Year | F1: Product Name | G1: Product Description | H1: Price | I1: Qty | J1: Notes
A2: POSM-001 | B2: POSM-001-V1 | C2: VEN-A | D2: =IFERROR(VLOOKUP(C2, Vendors!A:B, 2, FALSE), "-") -> Vendor A | E2: 2026 | F2: =IFERROR(VLOOKUP(A2, Products!$A:$C, 3, FALSE), "-") -> ร่มโค้ก | G2: =_xlfn.XLOOKUP(B2, Table2[Variant Code], Table2[Description], "ไม่มีรายละเอียดย่อย") -> 36 นิ้ว โครงเหล็ก สีตาย (ไม่เกิน 4 สี) | H2: 523 | I2: 1-99 ชิ้น
A3: POSM-001 | B3: POSM-001-V1 | C3: VEN-B | D3: =IFERROR(VLOOKUP(C3, Vendors!A:B, 2, FALSE), "-") -> Vendor B | E3: 2026 | F3: =IFERROR(VLOOKUP(A3, Products!$A:$C, 3, FALSE), "-") -> ร่มโค้ก | G3: =_xlfn.XLOOKUP(B3, Table2[Variant Code], Table2[Description], "ไม่มีรายละเอียดย่อย") -> 36 นิ้ว โครงเหล็ก สีตาย (ไม่เกิน 4 สี) | H3: 565 | I3: 100-499 ชิ้น
A4: POSM-001 | B4: POSM-001-V1 | C4: VEN-C | D4: =IFERROR(VLOOKUP(C4, Vendors!A:B, 2, FALSE), "-") -> Vendor C | E4: 2026 | F4: =IFERROR(VLOOKUP(A4, Products!$A:$C, 3, FALSE), "-") -> ร่มโค้ก | G4: =_xlfn.XLOOKUP(B4, Table2[Variant Code], Table2[Description], "ไม่มีรายละเอียดย่อย") -> 36 นิ้ว โครงเหล็ก สีตาย (ไม่เกิน 4 สี) | H4: 480 | I4: 500+ ชิ้น
A5: POSM-001 | B5: POSM-001-V2 | C5: VEN-A | D5: =IFERROR(VLOOKUP(C5, Vendors!A:B, 2, FALSE), "-") -> Vendor A | E5: 2026 | F5: =IFERROR(VLOOKUP(A5, Products!$A:$C, 3, FALSE), "-") -> ร่มโค้ก | G5: =_xlfn.XLOOKUP(B5, Table2[Variant Code], Table2[Description], "ไม่มีรายละเอียดย่อย") -> 36 นิ้ว โครงเหล็ก ไล่ระดับสี (ไม่เกิน 8 เฉด) | H5: 528 | I5: 1
A6: POSM-001 | B6: POSM-001-V3 | C6: VEN-A | D6: =IFERROR(VLOOKUP(C6, Vendors!A:B, 2, FALSE), "-") -> Vendor A | E6: 2026 | F6: =IFERROR(VLOOKUP(A6, Products!$A:$C, 3, FALSE), "-") -> ร่มโค้ก | G6: =_xlfn.XLOOKUP(B6, Table2[Variant Code], Table2[Description], "ไม่มีรายละเอียดย่อย") -> 36 นิ้ว โครงไฟเบอร์ สีตาย (ไม่เกิน 4 สี) | H6: 523 | I6: 1
A7: POSM-002 | C7: VEN-C | D7: =IFERROR(VLOOKUP(C7, Vendors!A:B, 2, FALSE), "-") -> Vendor C | E7: 2026 | F7: =IFERROR(VLOOKUP(A7, Products!$A:$C, 3, FALSE), "-") -> กล่องทิชชู-โค้ก | G7: =_xlfn.XLOOKUP(B7, Table2[Variant Code], Table2[Description], "ไม่มีรายละเอียดย่อย") -> ไม่มีรายละเอียดย่อย | H7: 28.5 | I7: 1-49 ชิ้น
A8: POSM-002 | C8: VEN-D | D8: =IFERROR(VLOOKUP(C8, Vendors!A:B, 2, FALSE), "-") -> Vendor D | E8: 2026 | F8: =IFERROR(VLOOKUP(A8, Products!$A:$C, 3, FALSE), "-") -> กล่องทิชชู-โค้ก | G8: =_xlfn.XLOOKUP(B8, Table2[Variant Code], Table2[Description], "ไม่มีรายละเอียดย่อย") -> ไม่มีรายละเอียดย่อย | H8: 30 | I8: 50-199 ชิ้น
A9: POSM-002 | C9: VEN-E | D9: =IFERROR(VLOOKUP(C9, Vendors!A:B, 2, FALSE), "-") -> Vendor E | E9: 2026 | F9: =IFERROR(VLOOKUP(A9, Products!$A:$C, 3, FALSE), "-") -> กล่องทิชชู-โค้ก | G9: =_xlfn.XLOOKUP(B9, Table2[Variant Code], Table2[Description], "ไม่มีรายละเอียดย่อย") -> ไม่มีรายละเอียดย่อย | H9: 25 | I9: 200+ ชิ้น
A10: POSM-003 | B10: POSM-003-V1 | C10: VEN-E | D10: =IFERROR(VLOOKUP(C10, Vendors!A:B, 2, FALSE), "-") -> Vendor E | E10: 2026 | F10: =IFERROR(VLOOKUP(A10, Products!$A:$C, 3, FALSE), "-") -> ผ้ากันเปื้อนโคคา-โคล่า | G10: =_xlfn.XLOOKUP(B10, Table2[Variant Code], Table2[Description], "ไม่มีรายละเอียดย่อย") -> เอี้ยม (เต็มตัว) ไขว้หลัง | H10: 65 | I10: 1
A11: POSM-003 | B11: POSM-003-V2 | C11: VEN-E | D11: =IFERROR(VLOOKUP(C11, Vendors!A:B, 2, FALSE), "-") -> Vendor E | E11: 2026 | F11: =IFERROR(VLOOKUP(A11, Products!$A:$C, 3, FALSE), "-") -> ผ้ากันเปื้อนโคคา-โคล่า | G11: =_xlfn.XLOOKUP(B11, Table2[Variant Code], Table2[Description], "ไม่มีรายละเอียดย่อย") -> ครึ่งตัว | H11: 55 | I11: 1
A12: POSM-006 | B12: POSM-006-V1 | C12: VEN-N | D12: =IFERROR(VLOOKUP(C12, Vendors!A:B, 2, FALSE), "-") -> Vendor N | E12: 2026 | F12: =IFERROR(VLOOKUP(A12, Products!$A:$C, 3, FALSE), "-") -> ธงปีกนก | G12: =_xlfn.XLOOKUP(B12, Table2[Variant Code], Table2[Description], "ไม่มีรายละเอียดย่อย") -> 120x40x150 cm (TT-DSD) | H12: 3500 | I12: 1-999 ชิ้น
A13: POSM-006 | B13: POSM-006-V2 | C13: VEN-N | D13: =IFERROR(VLOOKUP(C13, Vendors!A:B, 2, FALSE), "-") -> Vendor N | E13: 2026 | F13: =IFERROR(VLOOKUP(A13, Products!$A:$C, 3, FALSE), "-") -> ธงปีกนก | G13: =_xlfn.XLOOKUP(B13, Table2[Variant Code], Table2[Description], "ไม่มีรายละเอียดย่อย") -> 150x60x150 cm (WS) | H13: 3700 | I13: 1
A14: PRINT-001 | B14: PRINT-001-V1 | C14: VEN-F | D14: =IFERROR(VLOOKUP(C14, Vendors!A:B, 2, FALSE), "-") -> Vendor F | E14: 2026 | F14: =IFERROR(VLOOKUP(A14, Products!$A:$C, 3, FALSE), "-") -> PP Board | G14: =_xlfn.XLOOKUP(B14, Table2[Variant Code], Table2[Description], "ไม่มีรายละเอียดย่อย") -> 120x120 cm (โค้กเขียนชื่อร้านค้า) | H14: 580 | I14: 1
A15: PRINT-001 | B15: PRINT-001-V2 | C15: VEN-F | D15: =IFERROR(VLOOKUP(C15, Vendors!A:B, 2, FALSE), "-") -> Vendor F | E15: 2026 | F15: =IFERROR(VLOOKUP(A15, Products!$A:$C, 3, FALSE), "-") -> PP Board | G15: =_xlfn.XLOOKUP(B15, Table2[Variant Code], Table2[Description], "ไม่มีรายละเอียดย่อย") -> 85x190 cm (ป้ายหน้าเคาน์เตอร์) | H15: 450 | I15: 1000+ ชิ้น
A16: PRINT-001 | B16: PRINT-001-V3 | C16: VEN-F | D16: =IFERROR(VLOOKUP(C16, Vendors!A:B, 2, FALSE), "-") -> Vendor F | E16: 2026 | F16: =IFERROR(VLOOKUP(A16, Products!$A:$C, 3, FALSE), "-") -> PP Board | G16: =_xlfn.XLOOKUP(B16, Table2[Variant Code], Table2[Description], "ไม่มีรายละเอียดย่อย") -> 70x150 cm (ป้ายหน้าเคาน์เตอร์) | H16: 350 | I16: 1
A17: PRINT-002 | C17: VEN-G | D17: =IFERROR(VLOOKUP(C17, Vendors!A:B, 2, FALSE), "-") -> Vendor G | E17: 2026 | F17: =IFERROR(VLOOKUP(A17, Products!$A:$C, 3, FALSE), "-") -> ป้ายรายการอาหารโค้ก | G17: =_xlfn.XLOOKUP(B17, Table2[Variant Code], Table2[Description], "ไม่มีรายละเอียดย่อย") -> ไม่มีรายละเอียดย่อย | H17: 350 | I17: 1
A18: PRINT-005 | B18: PRINT-005-V1 | C18: VEN-H | D18: =IFERROR(VLOOKUP(C18, Vendors!A:B, 2, FALSE), "-") -> Vendor H | E18: 2026 | F18: =IFERROR(VLOOKUP(A18, Products!$A:$C, 3, FALSE), "-") -> แผ่นริจิ-โค้ก | G18: =_xlfn.XLOOKUP(B18, Table2[Variant Code], Table2[Description], "ไม่มีรายละเอียดย่อย") -> 16x24 นิ้ว | H18: 45 | I18: 1-24 ชิ้น
A19: PRINT-005 | B19: PRINT-005-V2 | C19: VEN-H | D19: =IFERROR(VLOOKUP(C19, Vendors!A:B, 2, FALSE), "-") -> Vendor H | E19: 2026 | F19: =IFERROR(VLOOKUP(A19, Products!$A:$C, 3, FALSE), "-") -> แผ่นริจิ-โค้ก | G19: =_xlfn.XLOOKUP(B19, Table2[Variant Code], Table2[Description], "ไม่มีรายละเอียดย่อย") -> 24x32 นิ้ว | H19: 60 | I19: 1
A20: GARMT-001 | B20: GARMT-001-V1 | C20: VEN-I | D20: =IFERROR(VLOOKUP(C20, Vendors!A:B, 2, FALSE), "-") -> Vendor I | E20: 2026 | F20: =IFERROR(VLOOKUP(A20, Products!$A:$C, 3, FALSE), "-") -> เสื้อยืด | G20: =_xlfn.XLOOKUP(B20, Table2[Variant Code], Table2[Description], "ไม่มีรายละเอียดย่อย") -> สีขาว | H20: 90 | I20: 25-99 ชิ้น
A21: GARMT-001 | B21: GARMT-001-V2 | C21: VEN-I | D21: =IFERROR(VLOOKUP(C21, Vendors!A:B, 2, FALSE), "-") -> Vendor I | E21: 2026 | F21: =IFERROR(VLOOKUP(A21, Products!$A:$C, 3, FALSE), "-") -> เสื้อยืด | G21: =_xlfn.XLOOKUP(B21, Table2[Variant Code], Table2[Description], "ไม่มีรายละเอียดย่อย") -> สีอ่อน | H21: 95 | I21: 1
A22: GARMT-001 | B22: GARMT-001-V3 | C22: VEN-I | D22: =IFERROR(VLOOKUP(C22, Vendors!A:B, 2, FALSE), "-") -> Vendor I | E22: 2026 | F22: =IFERROR(VLOOKUP(A22, Products!$A:$C, 3, FALSE), "-") -> เสื้อยืด | G22: =_xlfn.XLOOKUP(B22, Table2[Variant Code], Table2[Description], "ไม่มีรายละเอียดย่อย") -> สีกลาง | H22: 100 | I22: 1
A23: GARMT-001 | B23: GARMT-001-V4 | C23: VEN-I | D23: =IFERROR(VLOOKUP(C23, Vendors!A:B, 2, FALSE), "-") -> Vendor I | E23: 2026 | F23: =IFERROR(VLOOKUP(A23, Products!$A:$C, 3, FALSE), "-") -> เสื้อยืด | G23: =_xlfn.XLOOKUP(B23, Table2[Variant Code], Table2[Description], "ไม่มีรายละเอียดย่อย") -> สีเข้ม | H23: 110 | I23: 100-499 ชิ้น
A24: GARMT-001 | B24: GARMT-001-V1 | C24: VEN-O | D24: =IFERROR(VLOOKUP(C24, Vendors!A:B, 2, FALSE), "-") -> Vendor O | E24: 2026 | F24: =IFERROR(VLOOKUP(A24, Products!$A:$C, 3, FALSE), "-") -> เสื้อยืด | G24: =_xlfn.XLOOKUP(B24, Table2[Variant Code], Table2[Description], "ไม่มีรายละเอียดย่อย") -> สีขาว | H24: 75 | I24: 1
A25: GARMT-002 | B25: GARMT-002-V1 | C25: VEN-J | D25: =IFERROR(VLOOKUP(C25, Vendors!A:B, 2, FALSE), "-") -> Vendor J | E25: 2026 | F25: =IFERROR(VLOOKUP(A25, Products!$A:$C, 3, FALSE), "-") -> เสื้อโปโล TC | G25: =_xlfn.XLOOKUP(B25, Table2[Variant Code], Table2[Description], "ไม่มีรายละเอียดย่อย") -> ผ้า TC สีขาว | H25: 120 | I25: 1
A26: GARMT-002 | B26: GARMT-002-V3 | C26: VEN-J | D26: =IFERROR(VLOOKUP(C26, Vendors!A:B, 2, FALSE), "-") -> Vendor J | E26: 2026 | F26: =IFERROR(VLOOKUP(A26, Products!$A:$C, 3, FALSE), "-") -> เสื้อโปโล TC | G26: =_xlfn.XLOOKUP(B26, Table2[Variant Code], Table2[Description], "ไม่มีรายละเอียดย่อย") -> ผ้า TC สีกลาง | H26: 130 | I26: 500-999 ชิ้น
A27: GARMT-004 | B27: GARMT-004-V1 | C27: VEN-K | D27: =IFERROR(VLOOKUP(C27, Vendors!A:B, 2, FALSE), "-") -> Vendor K | E27: 2026 | F27: =IFERROR(VLOOKUP(A27, Products!$A:$C, 3, FALSE), "-") -> สกรีน | G27: =_xlfn.XLOOKUP(B27, Table2[Variant Code], Table2[Description], "ไม่มีรายละเอียดย่อย") -> 1 สี | H27: 25 | I27: 1
A28: GARMT-004 | B28: GARMT-004-V2 | C28: VEN-K | D28: =IFERROR(VLOOKUP(C28, Vendors!A:B, 2, FALSE), "-") -> Vendor K | E28: 2026 | F28: =IFERROR(VLOOKUP(A28, Products!$A:$C, 3, FALSE), "-") -> สกรีน | G28: =_xlfn.XLOOKUP(B28, Table2[Variant Code], Table2[Description], "ไม่มีรายละเอียดย่อย") -> 2 สี | H28: 30 | I28: 1
A29: GARMT-004 | B29: GARMT-004-V4 | C29: VEN-K | D29: =IFERROR(VLOOKUP(C29, Vendors!A:B, 2, FALSE), "-") -> Vendor K | E29: 2026 | F29: =IFERROR(VLOOKUP(A29, Products!$A:$C, 3, FALSE), "-") -> สกรีน | G29: =_xlfn.XLOOKUP(B29, Table2[Variant Code], Table2[Description], "ไม่มีรายละเอียดย่อย") -> 4 สี | H29: 40 | I29: 1000+ ชิ้น
A30: PREM-001 | B30: PREM-001-V1 | C30: VEN-L | D30: =IFERROR(VLOOKUP(C30, Vendors!A:B, 2, FALSE), "-") -> Vendor L | E30: 2026 | F30: =IFERROR(VLOOKUP(A30, Products!$A:$C, 3, FALSE), "-") -> แก้วกระดาษ | G30: =_xlfn.XLOOKUP(B30, Table2[Variant Code], Table2[Description], "ไม่มีรายละเอียดย่อย") -> 6.5 ออนซ์ | H30: 1.53 | I30: 1
A31: PREM-001 | B31: PREM-001-V2 | C31: VEN-L | D31: =IFERROR(VLOOKUP(C31, Vendors!A:B, 2, FALSE), "-") -> Vendor L | E31: 2026 | F31: =IFERROR(VLOOKUP(A31, Products!$A:$C, 3, FALSE), "-") -> แก้วกระดาษ | G31: =_xlfn.XLOOKUP(B31, Table2[Variant Code], Table2[Description], "ไม่มีรายละเอียดย่อย") -> 22 ออนซ์ | H31: 3.94 | I31: 1
A32: PREM-004 | B32: PREM-004-V1 | C32: VEN-M | D32: =IFERROR(VLOOKUP(C32, Vendors!A:B, 2, FALSE), "-") -> Vendor M | E32: 2026 | F32: =IFERROR(VLOOKUP(A32, Products!$A:$C, 3, FALSE), "-") -> Bean Bag | G32: =_xlfn.XLOOKUP(B32, Table2[Variant Code], Table2[Description], "ไม่มีรายละเอียดย่อย") -> หนังชามัวร์ | H32: 850 | I32: 1
A33: PREM-004 | B33: PREM-004-V2 | C33: VEN-M | D33: =IFERROR(VLOOKUP(C33, Vendors!A:B, 2, FALSE), "-") -> Vendor M | E33: 2026 | F33: =IFERROR(VLOOKUP(A33, Products!$A:$C, 3, FALSE), "-") -> Bean Bag | G33: =_xlfn.XLOOKUP(B33, Table2[Variant Code], Table2[Description], "ไม่มีรายละเอียดย่อย") -> วัสดุผ้า | H33: 800 | I33: 1
A34: POSM-006 | B34: POSM-006-V1 | C34: VEN-A | D34: =IFERROR(VLOOKUP(C34, Vendors!A:B, 2, FALSE), "-") -> Vendor A | F34: =IFERROR(VLOOKUP(A34, Products!$A:$C, 3, FALSE), "-") -> ธงปีกนก | G34: =_xlfn.XLOOKUP(B34, Table2[Variant Code], Table2[Description], "ไม่มีรายละเอียดย่อย") -> 120x40x150 cm (TT-DSD) | H34: 1000 | I34: 1
A35: POSM-007 | B35: POSM-007-v1 | C35: VEN-A | D35: =IFERROR(VLOOKUP(C35, Vendors!A:B, 2, FALSE), "-") -> Vendor A | F35: =IFERROR(VLOOKUP(A35, Products!$A:$C, 3, FALSE), "-") -> ฐานน้ำ | G35: =_xlfn.XLOOKUP(B35, Table2[Variant Code], Table2[Description], "ไม่มีรายละเอียดย่อย") -> 20 L | H35: 600 | I35: 1

Sheet PivotValues
B2: Min of Price | E2: Vendor Name
B3: Product Name | C3: Product Description | D3: Qty | E3: Vendor A | F3: Vendor B | G3: Vendor C | H3: Vendor D | I3: Vendor E | J3: Vendor F | K3: Vendor G | L3: Vendor H | M3: Vendor I | N3: Vendor J | O3: Vendor K | P3: Vendor L | Q3: Vendor M | R3: Vendor N | S3: Vendor O | T3: Grand Total
B4: Bean Bag | C4: หนังชามัวร์ | D4: 1 | Q4: 850 | T4: 850
C5: หนังชามัวร์ Total | Q5: 850 | T5: 850
C6: วัสดุผ้า | D6: 1 | Q6: 800 | T6: 800
C7: วัสดุผ้า Total | Q7: 800 | T7: 800
B8: Bean Bag Min | Q8: 800 | T8: 800
B9: PP Board | C9: 120x120 cm (โค้กเขียนชื่อร้านค้า) | D9: 1 | J9: 580 | T9: 580
C10: 120x120 cm (โค้กเขียนชื่อร้านค้า) Total | J10: 580 | T10: 580
C11: 85x190 cm (ป้ายหน้าเคาน์เตอร์) | D11: 1000+ ชิ้น | J11: 450 | T11: 450
C12: 85x190 cm (ป้ายหน้าเคาน์เตอร์) Total | J12: 450 | T12: 450
C13: 70x150 cm (ป้ายหน้าเคาน์เตอร์) | D13: 1 | J13: 350 | T13: 350
C14: 70x150 cm (ป้ายหน้าเคาน์เตอร์) Total | J14: 350 | T14: 350
B15: PP Board Min | J15: 350 | T15: 350
B16: เสื้อโปโล TC | C16: ผ้า TC สีขาว | D16: 1 | N16: 120 | T16: 120
C17: ผ้า TC สีขาว Total | N17: 120 | T17: 120
C18: ผ้า TC สีกลาง | D18: 500-999 ชิ้น | N18: 130 | T18: 130
C19: ผ้า TC สีกลาง Total | N19: 130 | T19: 130
B20: เสื้อโปโล TC Min | N20: 120 | T20: 120
B21: เสื้อยืด | C21: สีขาว | D21: 1 | S21: 75 | T21: 75
D22: 25-99 ชิ้น | M22: 90 | T22: 90
C23: สีขาว Total | M23: 90 | S23: 75 | T23: 75
C24: สีอ่อน | D24: 1 | M24: 95 | T24: 95
C25: สีอ่อน Total | M25: 95 | T25: 95
C26: สีกลาง | D26: 1 | M26: 100 | T26: 100
C27: สีกลาง Total | M27: 100 | T27: 100
C28: สีเข้ม | D28: 100-499 ชิ้น | M28: 110 | T28: 110
C29: สีเข้ม Total | M29: 110 | T29: 110
B30: เสื้อยืด Min | M30: 90 | S30: 75 | T30: 75
B31: แก้วกระดาษ | C31: 6.5 ออนซ์ | D31: 1 | P31: 1.53 | T31: 1.53
C32: 6.5 ออนซ์ Total | P32: 1.53 | T32: 1.53
C33: 22 ออนซ์ | D33: 1 | P33: 3.94 | T33: 3.94
C34: 22 ออนซ์ Total | P34: 3.94 | T34: 3.94
B35: แก้วกระดาษ Min | P35: 1.53 | T35: 1.53
B36: แผ่นริจิ-โค้ก | C36: 16x24 นิ้ว | D36: 1-24 ชิ้น | L36: 45 | T36: 45
C37: 16x24 นิ้ว Total | L37: 45 | T37: 45
C38: 24x32 นิ้ว | D38: 1 | L38: 60 | T38: 60
C39: 24x32 นิ้ว Total | L39: 60 | T39: 60
B40: แผ่นริจิ-โค้ก Min | L40: 45 | T40: 45
B41: กล่องทิชชู-โค้ก | C41: ไม่มีรายละเอียดย่อย | D41: 1-49 ชิ้น | G41: 28.5 | T41: 28.5
...
